Workbook

Sheet Instrucciones
A1: MODELO FINANCIERO — PROYECTO DE INVERSIÓN AGROINDUSTRIAL
A2: Curso: Formulación y Evaluación de Proyectos — horizonte de 10 años, moneda: soles (S/)
A4: CÓDIGO DE COLORES
A5: Azul sobre amarillo → celda que TÚ debes llenar (dato de entrada)
A6: Negro → fórmula calculada. No la toques.
A7: Verde → enlace a otra hoja del mismo archivo. No la toques.
A9: CÓMO USARLO
A10: 1. El archivo ya viene con un EJEMPLO COMPLETO cargado (planta de pulpa de mango congelada en Ica).
A11: Sirve para que veas cómo se conecta todo. Reemplaza los números por los tuyos y el modelo se recalcula solo.
A12: 2. Empieza por la hoja "Supuestos". Ahí está el 90 % de lo que debes cambiar.
A13: 3. Sigue con "Inversiones": pon tus cotizaciones reales de maquinaria, obra civil y equipos.
A14: 4. Todo lo demás (depreciación, deuda, estados, flujos, VAN y TIR) se calcula automáticamente.
... A18: ORDEN DE LAS HOJAS
A19: Supuestos | B19: Todos los datos de entrada: precios, costos unitarios, personal, tasas.
A20: Inversiones | B20: Inversión tangible, intangible y capital de trabajo. Estructura de financiamiento.
A21: Depreciacion | B21: Depreciación por activo y valor residual al año 10.
A22: Financiamiento | B22: Cuadro de amortización del préstamo (método de cuota constante).
A23: Operacion | B23: Producción, ingresos y costos año por año. Separa costos fijos de variables.
A24: EERR | B24: Estado de resultados proyectado.
A25: FlujoCaja | B25: Flujo de caja económico y flujo de caja financiero.
A26: Evaluacion | B26: VAN, TIR, B/C, periodo de recuperación, WACC y punto de equilibrio.
A27: Sensibilidad | B27: Sensibilidad al precio, al costo de materia prima y al volumen. Escenarios.
A30: ADVERTENCIA IMPORTANTE
A31: El ejemplo cargado usa cifras referenciales y NO son datos oficiales de ningún mercado.
A32: Antes de entregar, reemplaza cada dato por uno con fuente citable (INEI, MIDAGRI, SUNAT, SBS, cotizaciones reales).
A33: En el informe cada tabla debe llevar su fuente al pie. Un número sin fuente es la pregunta más fácil del jurado.

Sheet Supuestos
A1: SUPUESTOS DEL PROYECTO
A2: Cambia solo las celdas amarillas. Todo lo demás del archivo se recalcula solo.
A4: A. PARÁMETROS GENERALES
A5: Horizonte de evaluación | B5: 10 | C5: años
A6: Año base | B6: 2026
A7: Tipo de cambio | B7: 3.75 | C7: S/ por US$
A9: B. MERCADO Y PRODUCCIÓN
A10: Capacidad instalada de planta | B10: 720 | C10: t/año | D10: Sale del Capítulo III (tamaño del proyecto)
A11: Precio de venta del producto | B11: 8.5 | C11: S/ por kg | D11: Sale del Capítulo II (análisis de precios)
A12: Variación real del precio por año | B12: 0 | D12: Déjalo en 0 % si trabajas a precios constantes
A13: Rendimiento del proceso | B13: 0.55 | C13: kg PT / kg MP | D13: Sale del balance de materia
A15: C. COSTOS VARIABLES UNITARIOS
A16: Materia prima | B16: 1.8 | C16: S/ por kg de MP
A17: Insumos y aditivos | B17: 0.35 | C17: S/ por kg de PT
A18: Envases y embalaje | B18: 0.6 | C18: S/ por kg de PT
A19: Energía eléctrica y agua | B19: 0.22 | C19: S/ por kg de PT
A20: Distribución y transporte | B20: 0.18 | C20: S/ por kg de PT
A22: D. PERSONAL
A23: Factor de carga laboral (gratificaciones, CTS, EsSalud) | B23: 1.45 | C23: x sueldo
A25: Puesto | B25: Área | C25: N° de plazas | D25: Sueldo mensual (S/) | E25: Costo anual (S/)
A26: Jefe de planta | B26: Producción | C26: 1 | D26: 4500 | E26: =C26*D26*12*Supuestos!$B$23 -> 78300
A27: Supervisor de calidad | B27: Producción | C27: 1 | D27: 3000 | E27: =C27*D27*12*Supuestos!$B$23 -> 52200
A28: Operarios de proceso | B28: Producción | C28: 12 | D28: 1300 | E28: =C28*D28*12*Supuestos!$B$23 -> 271440
A29: Almacenero | B29: Producción | C29: 1 | D29: 1500 | E29: =C29*D29*12*Supuestos!$B$23 -> 26100
A30: Gerente / administrador | B30: Administración | C30: 1 | D30: 5000 | E30: =C30*D30*12*Supuestos!$B$23 -> 87000
A31: Asistente administrativo | B31: Administración | C31: 1 | D31: 1800 | E31: =C31*D31*12*Supuestos!$B$23 -> 31320
A32: Jefe de ventas | B32: Ventas | C32: 1 | D32: 3500 | E32: =C32*D32*12*Supuestos!$B$23 -> 60900
A33: Vendedor | B33: Ventas | C33: 2 | D33: 1600 | E33: =C33*D33*12*Supuestos!$B$23 -> 55680
A34: TOTAL PLANILLA ANUAL | E34: =SUM(E26:E33) -> 662940
A36: E. GASTOS FIJOS ANUALES
A37: Mantenimiento (% del valor de maquinaria y equipos) | B37: 0.03
A38: Alquiler de oficina y otros locales | B38: 24000 | C38: S/ al año
A39: Servicios de oficina, telefonía e internet | B39: 12000 | C39: S/ al año
A40: Seguros | B40: 15000 | C40: S/ al año
A41: Publicidad y promoción | B41: 30000 | C41: S/ al año
A42: Gestión ambiental y manejo de residuos | B42: 18000 | C42: S/ al año
A43: Otros gastos administrativos | B43: 10000 | C43: S/ al año
A45: F. TRIBUTOS Y TASAS
A46: Impuesto a la renta | B46: 0.295 | D46: Régimen general: 29.5 %
A47: Costo de oportunidad del capital (COK) | B47: 0.15 | D47: Justifícalo con CAPM o con la exigencia del inversionista
...

Sheet Inversiones
A1: INVERSIONES Y ESTRUCTURA DE FINANCIAMIENTO
A2: Reemplaza cantidades y costos unitarios por tus cotizaciones reales. Adjunta las cotizaciones como anexo.
A4: Concepto | B4: Cantidad | C4: Costo unitario (S/) | D4: Total (S/) | E4: Vida útil (años) | F4: Tasa dep. | G4: Nota
A5: A. INVERSIÓN FIJA TANGIBLE
A6: Terreno | B6: 1500 | C6: 120 | D6: =B6*C6 -> 180000 | E6: 0 | F6: 0 | G6: No se deprecia. m² × S//m²
A7: Obras civiles y edificaciones | B7: 1 | C7: 320000 | D7: =B7*C7 -> 320000 | E7: 20 | F7: 0.05 | G7: Tasa SUNAT 5 %
A8: Maquinaria y equipo de proceso | B8: 1 | C8: 420000 | D8: =B8*C8 -> 420000 | E8: 10 | F8: 0.1 | G8: Tasa SUNAT 10 %
A9: Cámara de frío y sistema de refrigeración | B9: 1 | C9: 95000 | D9: =B9*C9 -> 95000 | E9: 10 | F9: 0.1 | G9: Tasa SUNAT 10 %
A10: Equipos de laboratorio y control de calidad | B10: 1 | C10: 45000 | D10: =B10*C10 -> 45000 | E10: 10 | F10: 0.1 | G10: Tasa SUNAT 10 %
A11: Muebles y enseres | B11: 1 | C11: 25000 | D11: =B11*C11 -> 25000 | E11: 10 | F11: 0.1 | G11: Tasa SUNAT 10 %
A12: Equipos de cómputo | B12: 6 | C12: 3000 | D12: =B12*C12 -> 18000 | E12: 4 | F12: 0.25 | G12: Tasa SUNAT 25 %
A13: Vehículo de distribución | B13: 1 | C13: 85000 | D13: =B13*C13 -> 85000 | E13: 5 | F13: 0.2 | G13: Tasa SUNAT 20 %
A14: SUBTOTAL INVERSIÓN FIJA TANGIBLE | D14: =SUM(D6:D13) -> 1188000
A16: B. INVERSIÓN FIJA INTANGIBLE
A17: Estudios de preinversión y proyecto | D17: 18000
A18: Constitución de la empresa (SUNARP, notaría) | D18: 4500
A19: Licencia municipal de funcionamiento | D19: 6000
A20: Registro sanitario y habilitación DIGESA | D20: 3500
A21: Implementación de BPM, POES y plan HACCP | D21: 22000
A22: Software y sistemas de gestión | D22: 9000
A23: Capacitación del personal y puesta en marcha | D23: 15000
A24: Imprevistos (5 %) | D24: 4000
A25: SUBTOTAL INVERSIÓN FIJA INTANGIBLE | D25: =SUM(D17:D24) -> 82000 | G25: Se amortiza en 5 años (20 % anual)
A27: C. CAPITAL DE TRABAJO
A28: Costos operativos desembolsables del año 1 | D28: =Operacion!C$39 -> 2781558.2
A29: Meses de cobertura | D29: =Supuestos!$B$53 -> 3
A30: CAPITAL DE TRABAJO REQUERIDO | D30: =D28/12*D29 -> 695389.55 | G30: Método: meses de cobertura de costos operativos
A32: D. INVERSIÓN TOTAL
A33: INVERSIÓN TOTAL DEL PROYECTO | D33: =Inversiones!$D$14+Inversiones!$D$25+Inversiones!$D$30 -> 1965389.5
A35: E. ESTRUCTURA DE FINANCIAMIENTO
A36: Aporte propio (capital social) | D36: =Inversiones!$D$33*(1-Supuestos!$B$50) -> 786155.82 | E36: =D36/Inversiones!$D$33 -> 0.4
A37: Préstamo bancario | D37: =Inversiones!$D$33*Supuestos!$B$50 -> 1179233.7 | E37: =D37/Inversiones!$D$33 -> 0.6
A38: TOTAL | D38: =D36+D37 -> 1965389.5

Sheet Depreciacion
A1: DEPRECIACIÓN Y AMORTIZACIÓN
A2: Método lineal, tasas SUNAT. El valor en libros al año 10 es el valor residual del proyecto.
A4: Activo | B4: Unidad | C4: Año 1 | D4: Año 2 | E4: Año 3 | F4: Año 4 | G4: Año 5 | H4: Año 6 | I4: Año 7 | J4: Año 8 | K4: Año 9 | L4: Año 10
A5: =Inversiones!A6 -> Terreno | B5: =Inversiones!D6 -> 180000 | C5: =IF(1<=Inversiones!$E$6,$B$5*Inversiones!$F$6,0) -> 0 | D5: =IF(2<=Inversiones!$E$6,$B$5*Inversiones!$F$6,0) -> 0 | E5: =IF(3<=Inversiones!$E$6,$B$5*Inversiones!$F$6,0) -> 0 | F5: =IF(4<=Inversiones!$E$6,$B$5*Inversiones!$F$6,0) -> 0 | G5: =IF(5<=Inversiones!$E$6,$B$5*Inversiones!$F$6,0) -> 0 | H5: =IF(6<=Inversiones!$E$6,$B$5*Inversiones!$F$6,0) -> 0 | I5: =IF(7<=Inversiones!$E$6,$B$5*Inversiones!$F$6,0) -> 0 | J5: =IF(8<=Inversiones!$E$6,$B$5*Inversiones!$F$6,0) -> 0 | K5: =IF(9<=Inversiones!$E$6,$B$5*Inversiones!$F$6,0) -> 0 | L5: =IF(10<=Inversiones!$E$6,$B$5*Inversiones!$F$6,0) -> 0
A6: =Inversiones!A7 -> Obras civiles y edificaciones | B6: =Inversiones!D7 -> 320000 | C6: =IF(1<=Inversiones!$E$7,$B$6*Inversiones!$F$7,0) -> 16000 | D6: =IF(2<=Inversiones!$E$7,$B$6*Inversiones!$F$7,0) -> 16000 | E6: =IF(3<=Inversiones!$E$7,$B$6*Inversiones!$F$7,0) -> 16000 | F6: =IF(4<=Inversiones!$E$7,$B$6*Inversiones!$F$7,0) -> 16000 | G6: =IF(5<=Inversiones!$E$7,$B$6*Inversiones!$F$7,0) -> 16000 | H6: =IF(6<=Inversiones!$E$7,$B$6*Inversiones!$F$7,0) -> 16000 | I6: =IF(7<=Inversiones!$E$7,$B$6*Inversiones!$F$7,0) -> 16000 | J6: =IF(8<=Inversiones!$E$7,$B$6*Inversiones!$F$7,0) -> 16000 | K6: =IF(9<=Inversiones!$E$7,$B$6*Inversiones!$F$7,0) -> 16000 | L6: =IF(10<=Inversiones!$E$7,$B$6*Inversiones!$F$7,0) -> 16000
A7: =Inversiones!A8 -> Maquinaria y equipo de proceso | B7: =Inversiones!D8 -> 420000 | C7: =IF(1<=Inversiones!$E$8,$B$7*Inversiones!$F$8,0) -> 42000 | D7: =IF(2<=Inversiones!$E$8,$B$7*Inversiones!$F$8,0) -> 42000 | E7: =IF(3<=Inversiones!$E$8,$B$7*Inversiones!$F$8,0) -> 42000 | F7: =IF(4<=Inversiones!$E$8,$B$7*Inversiones!$F$8,0) -> 42000 | G7: =IF(5<=Inversiones!$E$8,$B$7*Inversiones!$F$8,0) -> 42000 | H7: =IF(6<=Inversiones!$E$8,$B$7*Inversiones!$F$8,0) -> 42000 | I7: =IF(7<=Inversiones!$E$8,$B$7*Inversiones!$F$8,0) -> 42000 | J7: =IF(8<=Inversiones!$E$8,$B$7*Inversiones!$F$8,0) -> 42000 | K7: =IF(9<=Inversiones!$E$8,$B$7*Inversiones!$F$8,0) -> 42000 | L7: =IF(10<=Inversiones!$E$8,$B$7*Inversiones!$F$8,0) -> 42000
A8: =Inversiones!A9 -> Cámara de frío y sistema de refrigeración | B8: =Inversiones!D9 -> 95000 | C8: =IF(1<=Inversiones!$E$9,$B$8*Inversiones!$F$9,0) -> 9500 | D8: =IF(2<=Inversiones!$E$9,$B$8*Inversiones!$F$9,0) -> 9500 | E8: =IF(3<=Inversiones!$E$9,$B$8*Inversiones!$F$9,0) -> 9500 | F8: =IF(4<=Inversiones!$E$9,$B$8*Inversiones!$F$9,0) -> 9500 | G8: =IF(5<=Inversiones!$E$9,$B$8*Inversiones!$F$9,0) -> 9500 | H8: =IF(6<=Inversiones!$E$9,$B$8*Inversiones!$F$9,0) -> 9500 | I8: =IF(7<=Inversiones!$E$9,$B$8*Inversiones!$F$9,0) -> 9500 | J8: =IF(8<=Inversiones!$E$9,$B$8*Inversiones!$F$9,0) -> 9500 | K8: =IF(9<=Inversiones!$E$9,$B$8*Inversiones!$F$9,0) -> 9500 | L8: =IF(10<=Inversiones!$E$9,$B$8*Inversiones!$F$9,0) -> 9500
A9: =Inversiones!A10 -> Equipos de laboratorio y control de calidad | B9: =Inversiones!D10 -> 45000 | C9: =IF(1<=Inversiones!$E$10,$B$9*Inversiones!$F$10,0) -> 4500 | D9: =IF(2<=Inversiones!$E$10,$B$9*Inversiones!$F$10,0) -> 4500 | E9: =IF(3<=Inversiones!$E$10,$B$9*Inversiones!$F$10,0) -> 4500 | F9: =IF(4<=Inversiones!$E$10,$B$9*Inversiones!$F$10,0) -> 4500 | G9: =IF(5<=Inversiones!$E$10,$B$9*Inversiones!$F$10,0) -> 4500 | H9: =IF(6<=Inversiones!$E$10,$B$9*Inversiones!$F$10,0) -> 4500 | I9: =IF(7<=Inversiones!$E$10,$B$9*Inversiones!$F$10,0) -> 4500 | J9: =IF(8<=Inversiones!$E$10,$B$9*Inversiones!$F$10,0) -> 4500 | K9: =IF(9<=Inversiones!$E$10,$B$9*Inversiones!$F$10,0) -> 4500 | L9: =IF(10<=Inversiones!$E$10,$B$9*Inversiones!$F$10,0) -> 4500
A10: =Inversiones!A11 -> Muebles y enseres | B10: =Inversiones!D11 -> 25000 | C10: =IF(1<=Inversiones!$E$11,$B$10*Inversiones!$F$11,0) -> 2500 | D10: =IF(2<=Inversiones!$E$11,$B$10*Inversiones!$F$11,0) -> 2500 | E10: =IF(3<=Inversiones!$E$11,$B$10*Inversiones!$F$11,0) -> 2500 | F10: =IF(4<=Inversiones!$E$11,$B$10*Inversiones!$F$11,0) -> 2500 | G10: =IF(5<=Inversiones!$E$11,$B$10*Inversiones!$F$11,0) -> 2500 | H10: =IF(6<=Inversiones!$E$11,$B$10*Inversiones!$F$11,0) -> 2500 | I10: =IF(7<=Inversiones!$E$11,$B$10*Inversiones!$F$11,0) -> 2500 | J10: =IF(8<=Inversiones!$E$11,$B$10*Inversiones!$F$11,0) -> 2500 | K10: =IF(9<=Inversiones!$E$11,$B$10*Inversiones!$F$11,0) -> 2500 | L10: =IF(10<=Inversiones!$E$11,$B$10*Inversiones!$F$11,0) -> 2500
A11: =Inversiones!A12 -> Equipos de cómputo | B11: =Inversiones!D12 -> 18000 | C11: =IF(1<=Inversiones!$E$12,$B$11*Inversiones!$F$12,0) -> 4500 | D11: =IF(2<=Inversiones!$E$12,$B$11*Inversiones!$F$12,0) -> 4500 | E11: =IF(3<=Inversiones!$E$12,$B$11*Inversiones!$F$12,0) -> 4500 | F11: =IF(4<=Inversiones!$E$12,$B$11*Inversiones!$F$12,0) -> 4500 | G11: =IF(5<=Inversiones!$E$12,$B$11*Inversiones!$F$12,0) -> 0 | H11: =IF(6<=Inversiones!$E$12,$B$11*Inversiones!$F$12,0) -> 0 | I11: =IF(7<=Inversiones!$E$12,$B$11*Inversiones!$F$12,0) -> 0 | J11: =IF(8<=Inversiones!$E$12,$B$11*Inversiones!$F$12,0) -> 0 | K11: =IF(9<=Inversiones!$E$12,$B$11*Inversiones!$F$12,0) -> 0 | L11: =IF(10<=Inversiones!$E$12,$B$11*Inversiones!$F$12,0) -> 0
A12: =Inversiones!A13 -> Vehículo de distribución | B12: =Inversiones!D13 -> 85000 | C12: =IF(1<=Inversiones!$E$13,$B$12*Inversiones!$F$13,0) -> 17000 | D12: =IF(2<=Inversiones!$E$13,$B$12*Inversiones!$F$13,0) -> 17000 | E12: =IF(3<=Inversiones!$E$13,$B$12*Inversiones!$F$13,0) -> 17000 | F12: =IF(4<=Inversiones!$E$13,$B$12*Inversiones!$F$13,0) -> 17000 | G12: =IF(5<=Inversiones!$E$13,$B$12*Inversiones!$F$13,0) -> 17000 | H12: =IF(6<=Inversiones!$E$13,$B$12*Inversiones!$F$13,0) -> 0 | I12: =IF(7<=Inversiones!$E$13,$B$12*Inversiones!$F$13,0) -> 0 | J12: =IF(8<=Inversiones!$E$13,$B$12*Inversiones!$F$13,0) -> 0 | K12: =IF(9<=Inversiones!$E$13,$B$12*Inversiones!$F$13,0) -> 0 | L12: =IF(10<=Inversiones!$E$13,$B$12*Inversiones!$F$13,0) -> 0
A13: Amortización de intangibles | B13: =Inversiones!$D$25 -> 82000 | C13: =IF(1<=5,$B$13*0.2,0) -> 16400 | D13: =IF(2<=5,$B$13*0.2,0) -> 16400 | E13: =IF(3<=5,$B$13*0.2,0) -> 16400 | F13: =IF(4<=5,$B$13*0.2,0) -> 16400 | G13: =IF(5<=5,$B$13*0.2,0) -> 16400 | H13: =IF(6<=5,$B$13*0.2,0) -> 0 | I13: =IF(7<=5,$B$13*0.2,0) -> 0 | J13: =IF(8<=5,$B$13*0.2,0) -> 0 | K13: =IF(9<=5,$B$13*0.2,0) -> 0 | L13: =IF(10<=5,$B$13*0.2,0) -> 0
A14: TOTAL DEPRECIACIÓN Y AMORTIZACIÓN | C14: =SUM(C5:C13) -> 112400 | D14: =SUM(D5:D13) -> 112400 | E14: =SUM(E5:E13) -> 112400 | F14: =SUM(F5:F13) -> 112400 | G14: =SUM(G5:G13) -> 107900 | H14: =SUM(H5:H13) -> 74500 | I14: =SUM(I5:I13) -> 74500 | J14: =SUM(J5:J13) -> 74500 | ... L14: =SUM(L5:L13) -> 74500
A16: VALOR RESIDUAL AL FINAL DEL HORIZONTE
A17: =Inversiones!A6 -> Terreno | B17: =B5-SUM(C5:L5) -> 180000 | C17: Valor en libros al año 10
A18: =Inversiones!A7 -> Obras civiles y edificaciones | B18: =B6-SUM(C6:L6) -> 160000 | C18: Valor en libros al año 10
A19: =Inversiones!A8 -> Maquinaria y equipo de proceso | B19: =B7-SUM(C7:L7) -> 0 | C19: Valor en libros al año 10
A20: =Inversiones!A9 -> Cámara de frío y sistema de refrigeración | B20: =B8-SUM(C8:L8) -> 0 | C20: Valor en libros al año 10
A21: =Inversiones!A10 -> Equipos de laboratorio y control de calidad | B21: =B9-SUM(C9:L9) -> 0 | C21: Valor en libros al año 10
A22: =Inversiones!A11 -> Muebles y enseres | B22: =B10-SUM(C10:L10) -> 0 | C22: Valor en libros al año 10
A23: =Inversiones!A12 -> Equipos de cómputo | B23: =B11-SUM(C11:L11) -> 0 | C23: Valor en libros al año 10
A24: =Inversiones!A13 -> Vehículo de distribución | B24: =B12-SUM(C12:L12) -> 0 | C24: Valor en libros al año 10
A25: VALOR RESIDUAL DE ACTIVOS FIJOS | B25: =SUM(B17:B24) -> 340000

Sheet Financiamiento
A1: SERVICIO DE LA DEUDA
A2: Préstamo con cuota constante (sistema francés). El interés es deducible de impuestos.
A4: Monto del préstamo (S/) | B4: =Inversiones!$D$37 -> 1179233.7
A5: Tasa efectiva anual (TEA) | B5: =Supuestos!$B$51 -> 0.14
A6: Plazo (años) | B6: =Supuestos!$B$52 -> 5
A7: Cuota anual constante (S/) | B7: =-PMT($B$5,$B$6,$B$4) -> 343491.38
A9: Año | B9: Saldo inicial | C9: Interés | D9: Amortización | E9: Cuota | F9: Saldo final
A10: 1 | B10: =$B$4 -> 1179233.7 | C10: =B10*$B$5 -> 165092.72 | D10: =E10-C10 -> 178398.66 | E10: =IF(1<=$B$6,$B$7,0) -> 343491.38 | F10: =MAX(B10-D10,0) -> 1000835.1
A11: 2 | B11: =F10 -> 1000835.1 | C11: =B11*$B$5 -> 140116.91 | D11: =E11-C11 -> 203374.47 | E11: =IF(2<=$B$6,$B$7,0) -> 343491.38 | F11: =MAX(B11-D11,0) -> 797460.59
A12: 3 | B12: =F11 -> 797460.59 | C12: =B12*$B$5 -> 111644.48 | D12: =E12-C12 -> 231846.9 | E12: =IF(3<=$B$6,$B$7,0) -> 343491.38 | F12: =MAX(B12-D12,0) -> 565613.69
A13: 4 | B13: =F12 -> 565613.69 | C13: =B13*$B$5 -> 79185.917 | D13: =E13-C13 -> 264305.46 | E13: =IF(4<=$B$6,$B$7,0) -> 343491.38 | F13: =MAX(B13-D13,0) -> 301308.23
A14: 5 | B14: =F13 -> 301308.23 | C14: =B14*$B$5 -> 42183.152 | D14: =E14-C14 -> 301308.23 | E14: =IF(5<=$B$6,$B$7,0) -> 343491.38 | F14: =MAX(B14-D14,0) -> 0
A15: 6 | B15: =F14 -> 0 | C15: =B15*$B$5 -> 0 | D15: =E15-C15 -> 0 | E15: =IF(6<=$B$6,$B$7,0) -> 0 | F15: =MAX(B15-D15,0) -> 0
A16: 7 | B16: =F15 -> 0 | C16: =B16*$B$5 -> 0 | D16: =E16-C16 -> 0 | E16: =IF(7<=$B$6,$B$7,0) -> 0 | F16: =MAX(B16-D16,0) -> 0
A17: 8 | B17: =F16 -> 0 | C17: =B17*$B$5 -> 0 | D17: =E17-C17 -> 0 | E17: =IF(8<=$B$6,$B$7,0) -> 0 | F17: =MAX(B17-D17,0) -> 0
A18: 9 | B18: =F17 -> 0 | C18: =B18*$B$5 -> 0 | D18: =E18-C18 -> 0 | E18: =IF(9<=$B$6,$B$7,0) -> 0 | F18: =MAX(B18-D18,0) -> 0
A19: 10 | B19: =F18 -> 0 | C19: =B19*$B$5 -> 0 | D19: =E19-C19 -> 0 | E19: =IF(10<=$B$6,$B$7,0) -> 0 | F19: =MAX(B19-D19,0) -> 0
A20: TOTAL | C20: =SUM(C10:C19) -> 538223.18 | D20: =SUM(D10:D19) -> 1179233.7 | E20: =SUM(E10:E19) -> 1717456.9

Sheet Operacion
A1: PRODUCCIÓN, INGRESOS Y COSTOS OPERATIVOS
A2: Todo se calcula a partir de la hoja Supuestos. Los costos están separados en variables y fijos para el punto de equilibrio.
A4: Concepto | B4: Unidad | C4: Año 1 | D4: Año 2 | E4: Año 3 | F4: Año 4 | G4: Año 5 | H4: Año 6 | I4: Año 7 | J4: Año 8 | K4: Año 9 | L4: Año 10
A5: A. PROGRAMA DE PRODUCCIÓN
A6: Producción (t/año) | B6: t | C6: =Supuestos!$B$10*Supuestos!C$58 -> 432 | D6: =Supuestos!$B$10*Supuestos!D$58 -> 489.6 | E6: =Supuestos!$B$10*Supuestos!E$58 -> 540 | F6: =Supuestos!$B$10*Supuestos!F$58 -> 576 | G6: =Supuestos!$B$10*Supuestos!G$58 -> 612 | H6: =Supuestos!$B$10*Supuestos!H$58 -> 633.6 | I6: =Supuestos!$B$10*Supuestos!I$58 -> 648 | J6: =Supuestos!$B$10*Supuestos!J$58 -> 648 | ... L6: =Supuestos!$B$10*Supuestos!L$58 -> 648
A7: Producción (kg/año) | B7: kg | C7: =C6*1000 -> 432000 | D7: =D6*1000 -> 489600 | E7: =E6*1000 -> 540000 | F7: =F6*1000 -> 576000 | G7: =G6*1000 -> 612000 | H7: =H6*1000 -> 633600 | I7: =I6*1000 -> 648000 | J7: =J6*1000 -> 648000 | ... L7: =L6*1000 -> 648000
A8: Materia prima requerida (kg) | B8: kg | C8: =C7/Supuestos!$B$13 -> 785454.55 | D8: =D7/Supuestos!$B$13 -> 890181.82 | E8: =E7/Supuestos!$B$13 -> 981818.18 | F8: =F7/Supuestos!$B$13 -> 1047272.7 | G8: =G7/Supuestos!$B$13 -> 1112727.3 | H8: =H7/Supuestos!$B$13 -> 1152000 | I8: =I7/Supuestos!$B$13 -> 1178181.8 | J8: =J7/Supuestos!$B$13 -> 1178181.8 | ... L8: =L7/Supuestos!$B$13 -> 1178181.8
A9: Precio de venta (S/ por kg) | B9: S/ | C9: =Supuestos!$B$11*(1+Supuestos!$B$12)^0 -> 8.5 | D9: =Supuestos!$B$11*(1+Supuestos!$B$12)^1 -> 8.5 | E9: =Supuestos!$B$11*(1+Supuestos!$B$12)^2 -> 8.5 | F9: =Supuestos!$B$11*(1+Supuestos!$B$12)^3 -> 8.5 | G9: =Supuestos!$B$11*(1+Supuestos!$B$12)^4 -> 8.5 | H9: =Supuestos!$B$11*(1+Supuestos!$B$12)^5 -> 8.5 | I9: =Supuestos!$B$11*(1+Supuestos!$B$12)^6 -> 8.5 | J9: =Supuestos!$B$11*(1+Supuestos!$B$12)^7 -> 8.5 | K9: =Supuestos!$B$11*(1+Supuestos!$B$12)^8 -> 8.5 | L9: =Supuestos!$B$11*(1+Supuestos!$B$12)^9 -> 8.5
A11: B. INGRESOS
A12: INGRESOS POR VENTAS (S/) | B12: S/ | C12: =C7*C9 -> 3672000 | D12: =D7*D9 -> 4161600 | E12: =E7*E9 -> 4590000 | F12: =F7*F9 -> 4896000 | G12: =G7*G9 -> 5202000 | H12: =H7*H9 -> 5385600 | I12: =I7*I9 -> 5508000 | J12: =J7*J9 -> 5508000 | ... L12: =L7*L9 -> 5508000
A14: C. COSTOS VARIABLES
A15: Materia prima | B15: S/ | C15: =C8*Supuestos!$B$16 -> 1413818.2 | D15: =D8*Supuestos!$B$16 -> 1602327.3 | E15: =E8*Supuestos!$B$16 -> 1767272.7 | F15: =F8*Supuestos!$B$16 -> 1885090.9 | G15: =G8*Supuestos!$B$16 -> 2002909.1 | H15: =H8*Supuestos!$B$16 -> 2073600 | I15: =I8*Supuestos!$B$16 -> 2120727.3 | J15: =J8*Supuestos!$B$16 -> 2120727.3 | ... L15: =L8*Supuestos!$B$16 -> 2120727.3
A16: Insumos y aditivos | B16: S/ | C16: =C7*Supuestos!$B$17 -> 151200 | D16: =D7*Supuestos!$B$17 -> 171360 | E16: =E7*Supuestos!$B$17 -> 189000 | F16: =F7*Supuestos!$B$17 -> 201600 | G16: =G7*Supuestos!$B$17 -> 214200 | H16: =H7*Supuestos!$B$17 -> 221760 | I16: =I7*Supuestos!$B$17 -> 226800 | J16: =J7*Supuestos!$B$17 -> 226800 | ... L16: =L7*Supuestos!$B$17 -> 226800
A17: Envases y embalaje | B17: S/ | C17: =C7*Supuestos!$B$18 -> 259200 | D17: =D7*Supuestos!$B$18 -> 293760 | E17: =E7*Supuestos!$B$18 -> 324000 | F17: =F7*Supuestos!$B$18 -> 345600 | G17: =G7*Supuestos!$B$18 -> 367200 | H17: =H7*Supuestos!$B$18 -> 380160 | I17: =I7*Supuestos!$B$18 -> 388800 | J17: =J7*Supuestos!$B$18 -> 388800 | ... L17: =L7*Supuestos!$B$18 -> 388800
A18: Energía eléctrica y agua | B18: S/ | C18: =C7*Supuestos!$B$19 -> 95040 | D18: =D7*Supuestos!$B$19 -> 107712 | E18: =E7*Supuestos!$B$19 -> 118800 | F18: =F7*Supuestos!$B$19 -> 126720 | G18: =G7*Supuestos!$B$19 -> 134640 | H18: =H7*Supuestos!$B$19 -> 139392 | I18: =I7*Supuestos!$B$19 -> 142560 | J18: =J7*Supuestos!$B$19 -> 142560 | ... L18: =L7*Supuestos!$B$19 -> 142560
A19: Distribución y transporte | B19: S/ | C19: =C7*Supuestos!$B$20 -> 77760 | D19: =D7*Supuestos!$B$20 -> 88128 | E19: =E7*Supuestos!$B$20 -> 97200 | F19: =F7*Supuestos!$B$20 -> 103680 | G19: =G7*Supuestos!$B$20 -> 110160 | H19: =H7*Supuestos!$B$20 -> 114048 | I19: =I7*Supuestos!$B$20 -> 116640 | J19: =J7*Supuestos!$B$20 -> 116640 | ... L19: =L7*Supuestos!$B$20 -> 116640
A20: TOTAL COSTOS VARIABLES | B20: S/ | C20: =SUM(C15:C19) -> 1997018.2 | D20: =SUM(D15:D19) -> 2263287.3 | E20: =SUM(E15:E19) -> 2496272.7 | F20: =SUM(F15:F19) -> 2662690.9 | G20: =SUM(G15:G19) -> 2829109.1 | H20: =SUM(H15:H19) -> 2928960 | I20: =SUM(I15:I19) -> 2995527.3 | J20: =SUM(J15:J19) -> 2995527.3 | ... L20: =SUM(L15:L19) -> 2995527.3
A22: D. COSTOS FIJOS
A23: Mano de obra de producción | B23: S/ | C23: =SUMIFS(Supuestos!$E$26:$E$33,Supuestos!$B$26:$B$33,"Producción") -> 428040 | D23: =SUMIFS(Supuestos!$E$26:$E$33,Supuestos!$B$26:$B$33,"Producción") -> 428040 | E23: =SUMIFS(Supuestos!$E$26:$E$33,Supuestos!$B$26:$B$33,"Producción") -> 428040 | F23: =SUMIFS(Supuestos!$E$26:$E$33,Supuestos!$B$26:$B$33,"Producción") -> 428040 | G23: =SUMIFS(Supuestos!$E$26:$E$33,Supuestos!$B$26:$B$33,"Producción") -> 428040 | H23: =SUMIFS(Supuestos!$E$26:$E$33,Supuestos!$B$26:$B$33,"Producción") -> 428040 | I23: =SUMIFS(Supuestos!$E$26:$E$33,Supuestos!$B$26:$B$33,"Producción") -> 428040 | J23: =SUMIFS(Supuestos!$E$26:$E$33,Supuestos!$B$26:$B$33,"Producción") -> 428040 | ... L23: =SUMIFS(Supuestos!$E$26:$E$33,Supuestos!$B$26:$B$33,"Producción") -> 428040
A24: Mantenimiento de maquinaria | B24: S/ | C24: =Inversiones!$D$8*Supuestos!$B$37 -> 12600 | D24: =Inversiones!$D$8*Supuestos!$B$37 -> 12600 | E24: =Inversiones!$D$8*Supuestos!$B$37 -> 12600 | F24: =Inversiones!$D$8*Supuestos!$B$37 -> 12600 | G24: =Inversiones!$D$8*Supuestos!$B$37 -> 12600 | H24: =Inversiones!$D$8*Supuestos!$B$37 -> 12600 | I24: =Inversiones!$D$8*Supuestos!$B$37 -> 12600 | J24: =Inversiones!$D$8*Supuestos!$B$37 -> 12600 | ... L24: =Inversiones!$D$8*Supuestos!$B$37 -> 12600
A25: Gestión ambiental y manejo de residuos | B25: S/ | C25: =Supuestos!$B$42 -> 18000 | D25: =Supuestos!$B$42 -> 18000 | E25: =Supuestos!$B$42 -> 18000 | F25: =Supuestos!$B$42 -> 18000 | G25: =Supuestos!$B$42 -> 18000 | H25: =Supuestos!$B$42 -> 18000 | I25: =Supuestos!$B$42 -> 18000 | J25: =Supuestos!$B$42 -> 18000 | ... L25: =Supuestos!$B$42 -> 18000
A26: Planilla administrativa | B26: S/ | C26: =SUMIFS(Supuestos!$E$26:$E$33,Supuestos!$B$26:$B$33,"Administración") -> 118320 | D26: =SUMIFS(Supuestos!$E$26:$E$33,Supuestos!$B$26:$B$33,"Administración") -> 118320 | E26: =SUMIFS(Supuestos!$E$26:$E$33,Supuestos!$B$26:$B$33,"Administración") -> 118320 | F26: =SUMIFS(Supuestos!$E$26:$E$33,Supuestos!$B$26:$B$33,"Administración") -> 118320 | G26: =SUMIFS(Supuestos!$E$26:$E$33,Supuestos!$B$26:$B$33,"Administración") -> 118320 | H26: =SUMIFS(Supuestos!$E$26:$E$33,Supuestos!$B$26:$B$33,"Administración") -> 118320 | I26: =SUMIFS(Supuestos!$E$26:$E$33,Supuestos!$B$26:$B$33,"Administración") -> 118320 | J26: =SUMIFS(Supuestos!$E$26:$E$33,Supuestos!$B$26:$B$33,"Administración") -> 118320 | ... L26: =SUMIFS(Supuestos!$E$26:$E$33,Supuestos!$B$26:$B$33,"Administración") -> 118320
A27: Alquileres | B27: S/ | C27: =Supuestos!$B$38 -> 24000 | D27: =Supuestos!$B$38 -> 24000 | E27: =Supuestos!$B$38 -> 24000 | F27: =Supuestos!$B$38 -> 24000 | G27: =Supuestos!$B$38 -> 24000 | H27: =Supuestos!$B$38 -> 24000 | I27: =Supuestos!$B$38 -> 24000 | J27: =Supuestos!$B$38 -> 24000 | ... L27: =Supuestos!$B$38 -> 24000
A28: Servicios de oficina | B28: S/ | C28: =Supuestos!$B$39 -> 12000 | D28: =Supuestos!$B$39 -> 12000 | E28: =Supuestos!$B$39 -> 12000 | F28: =Supuestos!$B$39 -> 12000 | G28: =Supuestos!$B$39 -> 12000 | H28: =Supuestos!$B$39 -> 12000 | I28: =Supuestos!$B$39 -> 12000 | J28: =Supuestos!$B$39 -> 12000 | ... L28: =Supuestos!$B$39 -> 12000
A29: Seguros | B29: S/ | C29: =Supuestos!$B$40 -> 15000 | D29: =Supuestos!$B$40 -> 15000 | E29: =Supuestos!$B$40 -> 15000 | F29: =Supuestos!$B$40 -> 15000 | G29: =Supuestos!$B$40 -> 15000 | H29: =Supuestos!$B$40 -> 15000 | I29: =Supuestos!$B$40 -> 15000 | J29: =Supuestos!$B$40 -> 15000 | ... L29: =Supuestos!$B$40 -> 15000
A30: Otros gastos administrativos | B30: S/ | C30: =Supuestos!$B$43 -> 10000 | D30: =Supuestos!$B$43 -> 10000 | E30: =Supuestos!$B$43 -> 10000 | F30: =Supuestos!$B$43 -> 10000 | G30: =Supuestos!$B$43 -> 10000 | H30: =Supuestos!$B$43 -> 10000 | I30: =Supuestos!$B$43 -> 10000 | J30: =Supuestos!$B$43 -> 10000 | ... L30: =Supuestos!$B$43 -> 10000
A31: Planilla de ventas | B31: S/ | C31: =SUMIFS(Supuestos!$E$26:$E$33,Supuestos!$B$26:$B$33,"Ventas") -> 116580 | D31: =SUMIFS(Supuestos!$E$26:$E$33,Supuestos!$B$26:$B$33,"Ventas") -> 116580 | E31: =SUMIFS(Supuestos!$E$26:$E$33,Supuestos!$B$26:$B$33,"Ventas") -> 116580 | F31: =SUMIFS(Supuestos!$E$26:$E$33,Supuestos!$B$26:$B$33,"Ventas") -> 116580 | G31: =SUMIFS(Supuestos!$E$26:$E$33,Supuestos!$B$26:$B$33,"Ventas") -> 116580 | H31: =SUMIFS(Supuestos!$E$26:$E$33,Supuestos!$B$26:$B$33,"Ventas") -> 116580 | I31: =SUMIFS(Supuestos!$E$26:$E$33,Supuestos!$B$26:$B$33,"Ventas") -> 116580 | J31: =SUMIFS(Supuestos!$E$26:$E$33,Supuestos!$B$26:$B$33,"Ventas") -> 116580 | ... L31: =SUMIFS(Supuestos!$E$26:$E$33,Supuestos!$B$26:$B$33,"Ventas") -> 116580
A32: Publicidad y promoción | B32: S/ | C32: =Supuestos!$B$41 -> 30000 | D32: =Supuestos!$B$41 -> 30000 | E32: =Supuestos!$B$41 -> 30000 | F32: =Supuestos!$B$41 -> 30000 | G32: =Supuestos!$B$41 -> 30000 | H32: =Supuestos!$B$41 -> 30000 | I32: =Supuestos!$B$41 -> 30000 | J32: =Supuestos!$B$41 -> 30000 | ... L32: =Supuestos!$B$41 -> 30000
A33: TOTAL COSTOS FIJOS | B33: S/ | C33: =SUM(C23:C32) -> 784540 | D33: =SUM(D23:D32) -> 784540 | E33: =SUM(E23:E32) -> 784540 | F33: =SUM(F23:F32) -> 784540 | G33: =SUM(G23:G32) -> 784540 | H33: =SUM(H23:H32) -> 784540 | I33: =SUM(I23:I32) -> 784540 | J33: =SUM(J23:J32) -> 784540 | ... L33: =SUM(L23:L32) -> 784540
A35: E. RESÚMENES
A36: Costo de producción (variables + fijos de planta) | B36: S/ | C36: =C20+SUM(C23:C25) -> 2455658.2 | D36: =D20+SUM(D23:D25) -> 2721927.3 | E36: =E20+SUM(E23:E25) -> 2954912.7 | F36: =F20+SUM(F23:F25) -> 3121330.9 | G36: =G20+SUM(G23:G25) -> 3287749.1 | H36: =H20+SUM(H23:H25) -> 3387600 | I36: =I20+SUM(I23:I25) -> 3454167.3 | J36: =J20+SUM(J23:J25) -> 3454167.3 | ... L36: =L20+SUM(L23:L25) -> 3454167.3
A37: Gastos administrativos | B37: S/ | C37: =SUM(C26:C30) -> 179320 | D37: =SUM(D26:D30) -> 179320 | E37: =SUM(E26:E30) -> 179320 | F37: =SUM(F26:F30) -> 179320 | G37: =SUM(G26:G30) -> 179320 | H37: =SUM(H26:H30) -> 179320 | I37: =SUM(I26:I30) -> 179320 | J37: =SUM(J26:J30) -> 179320 | ... L37: =SUM(L26:L30) -> 179320
A38: Gastos de ventas | B38: S/ | C38: =SUM(C31:C32) -> 146580 | D38: =SUM(D31:D32) -> 146580 | E38: =SUM(E31:E32) -> 146580 | F38: =SUM(F31:F32) -> 146580 | G38: =SUM(G31:G32) -> 146580 | H38: =SUM(H31:H32) -> 146580 | I38: =SUM(I31:I32) -> 146580 | J38: =SUM(J31:J32) -> 146580 | ... L38: =SUM(L31:L32) -> 146580
A39: TOTAL COSTOS OPERATIVOS DESEMBOLSABLES (sin depreciación) | B39: S/ | C39: =C20+C33 -> 2781558.2 | D39: =D20+D33 -> 3047827.3 | E39: =E20+E33 -> 3280812.7 | F39: =F20+F33 -> 3447230.9 | G39: =G20+G33 -> 3613649.1 | H39: =H20+H33 -> 3713500 | I39: =I20+I33 -> 3780067.3 | J39: =J20+J33 -> 3780067.3 | ... L39: =L20+L33 -> 3780067.3
A40: Costo variable unitario (S/ por kg) | B40: S/ | C40: =IF(C7=0,0,C20/C7) -> 4.6227273 | D40: =IF(D7=0,0,D20/D7) -> 4.6227273 | E40: =IF(E7=0,0,E20/E7) -> 4.6227273 | F40: =IF(F7=0,0,F20/F7) -> 4.6227273 | G40: =IF(G7=0,0,G20/G7) -> 4.6227273 | H40: =IF(H7=0,0,H20/H7) -> 4.6227273 | I40: =IF(I7=0,0,I20/I7) -> 4.6227273 | J40: =IF(J7=0,0,J20/J7) -> 4.6227273 | ... L40: =IF(L7=0,0,L20/L7) -> 4.6227273

Sheet EERR
A1: ESTADO DE RESULTADOS PROYECTADO
A2: Expresado en soles corrientes. Incluye el efecto de la deuda.
A4: Concepto | B4: Unidad | C4: Año 1 | D4: Año 2 | E4: Año 3 | F4: Año 4 | G4: Año 5 | H4: Año 6 | I4: Año 7 | J4: Año 8 | K4: Año 9 | L4: Año 10
A5: Ventas netas | C5: =Operacion!C$12 -> 3672000 | D5: =Operacion!D$12 -> 4161600 | E5: =Operacion!E$12 -> 4590000 | F5: =Operacion!F$12 -> 4896000 | G5: =Operacion!G$12 -> 5202000 | H5: =Operacion!H$12 -> 5385600 | I5: =Operacion!I$12 -> 5508000 | J5: =Operacion!J$12 -> 5508000 | ... L5: =Operacion!L$12 -> 5508000
A6: (-) Costo de producción | C6: =-Operacion!C$36 -> -2455658.2 | D6: =-Operacion!D$36 -> -2721927.3 | E6: =-Operacion!E$36 -> -2954912.7 | F6: =-Operacion!F$36 -> -3121330.9 | G6: =-Operacion!G$36 -> -3287749.1 | H6: =-Operacion!H$36 -> -3387600 | I6: =-Operacion!I$36 -> -3454167.3 | J6: =-Operacion!J$36 -> -3454167.3 | ... L6: =-Operacion!L$36 -> -3454167.3
A7: UTILIDAD BRUTA | C7: =C5+C6 -> 1216341.8 | D7: =D5+D6 -> 1439672.7 | E7: =E5+E6 -> 1635087.3 | F7: =F5+F6 -> 1774669.1 | G7: =G5+G6 -> 1914250.9 | H7: =H5+H6 -> 1998000 | I7: =I5+I6 -> 2053832.7 | J7: =J5+J6 -> 2053832.7 | ... L7: =L5+L6 -> 2053832.7
A8: (-) Gastos administrativos | C8: =-Operacion!C$37 -> -179320 | D8: =-Operacion!D$37 -> -179320 | E8: =-Operacion!E$37 -> -179320 | F8: =-Operacion!F$37 -> -179320 | G8: =-Operacion!G$37 -> -179320 | H8: =-Operacion!H$37 -> -179320 | I8: =-Operacion!I$37 -> -179320 | J8: =-Operacion!J$37 -> -179320 | ... L8: =-Operacion!L$37 -> -179320
A9: (-) Gastos de ventas | C9: =-Operacion!C$38 -> -146580 | D9: =-Operacion!D$38 -> -146580 | E9: =-Operacion!E$38 -> -146580 | F9: =-Operacion!F$38 -> -146580 | G9: =-Operacion!G$38 -> -146580 | H9: =-Operacion!H$38 -> -146580 | I9: =-Operacion!I$38 -> -146580 | J9: =-Operacion!J$38 -> -146580 | ... L9: =-Operacion!L$38 -> -146580
A10: (-) Depreciación y amortización | C10: =-Depreciacion!C$14 -> -112400 | D10: =-Depreciacion!D$14 -> -112400 | E10: =-Depreciacion!E$14 -> -112400 | F10: =-Depreciacion!F$14 -> -112400 | G10: =-Depreciacion!G$14 -> -107900 | H10: =-Depreciacion!H$14 -> -74500 | I10: =-Depreciacion!I$14 -> -74500 | J10: =-Depreciacion!J$14 -> -74500 | ... L10: =-Depreciacion!L$14 -> -74500
A11: UTILIDAD OPERATIVA (EBIT) | C11: =C7+C8+C9+C10 -> 778041.82 | D11: =D7+D8+D9+D10 -> 1001372.7 | E11: =E7+E8+E9+E10 -> 1196787.3 | F11: =F7+F8+F9+F10 -> 1336369.1 | G11: =G7+G8+G9+G10 -> 1480450.9 | H11: =H7+H8+H9+H10 -> 1597600 | I11: =I7+I8+I9+I10 -> 1653432.7 | J11: =J7+J8+J9+J10 -> 1653432.7 | ... L11: =L7+L8+L9+L10 -> 1653432.7
A12: (-) Gastos financieros (intereses) | C12: =-Financiamiento!$C$10 -> -165092.72 | D12: =-Financiamiento!$C$11 -> -140116.91 | E12: =-Financiamiento!$C$12 -> -111644.48 | F12: =-Financiamiento!$C$13 -> -79185.917 | G12: =-Financiamiento!$C$14 -> -42183.152 | H12: =-Financiamiento!$C$15 -> 0 | I12: =-Financiamiento!$C$16 -> 0 | J12: =-Financiamiento!$C$17 -> 0 | K12: =-Financiamiento!$C$18 -> 0 | L12: =-Financiamiento!$C$19 -> 0
A13: UTILIDAD ANTES DE IMPUESTOS | C13: =C11+C12 -> 612949.1 | D13: =D11+D12 -> 861255.82 | E13: =E11+E12 -> 1085142.8 | F13: =F11+F12 -> 1257183.2 | G13: =G11+G12 -> 1438267.8 | H13: =H11+H12 -> 1597600 | I13: =I11+I12 -> 1653432.7 | J13: =J11+J12 -> 1653432.7 | ... L13: =L11+L12 -> 1653432.7
A14: (-) Impuesto a la renta | C14: =-MAX(C13,0)*Supuestos!$B$46 -> -180819.98 | D14: =-MAX(D13,0)*Supuestos!$B$46 -> -254070.47 | E14: =-MAX(E13,0)*Supuestos!$B$46 -> -320117.12 | F14: =-MAX(F13,0)*Supuestos!$B$46 -> -370869.04 | G14: =-MAX(G13,0)*Supuestos!$B$46 -> -424288.99 | H14: =-MAX(H13,0)*Supuestos!$B$46 -> -471292 | I14: =-MAX(I13,0)*Supuestos!$B$46 -> -487762.65 | J14: =-MAX(J13,0)*Supuestos!$B$46 -> -487762.65 | ... L14: =-MAX(L13,0)*Supuestos!$B$46 -> -487762.65
A15: UTILIDAD NETA | C15: =C13+C14 -> 432129.11 | D15: =D13+D14 -> 607185.35 | E15: =E13+E14 -> 765025.67 | F15: =F13+F14 -> 886314.14 | G15: =G13+G14 -> 1013978.8 | H15: =H13+H14 -> 1126308 | I15: =I13+I14 -> 1165670.1 | J15: =J13+J14 -> 1165670.1 | ... L15: =L13+L14 -> 1165670.1
A17: Margen neto sobre ventas | C17: =IF(C5=0,0,C15/C5) -> 0.11768222 | D17: =IF(D5=0,0,D15/D5) -> 0.1459019 | E17: =IF(E5=0,0,E15/E5) -> 0.16667226 | F17: =IF(F5=0,0,F15/F5) -> 0.18102821 | G17: =IF(G5=0,0,G15/G5) -> 0.19492095 | H17: =IF(H5=0,0,H15/H5) -> 0.20913324 | I17: =IF(I5=0,0,I15/I5) -> 0.21163218 | J17: =IF(J5=0,0,J15/J5) -> 0.21163218 | ... L17: =IF(L5=0,0,L15/L5) -> 0.21163218

Sheet FlujoCaja
A1: FLUJO DE CAJA ECONÓMICO Y FINANCIERO
A2: El flujo económico evalúa el negocio en sí. El flujo financiero evalúa lo que gana el accionista con deuda.
A4: Concepto | B4: Año 0 | C4: Año 1 | D4: Año 2 | E4: Año 3 | F4: Año 4 | G4: Año 5 | H4: Año 6 | I4: Año 7 | J4: Año 8 | K4: Año 9 | L4: Año 10
A5: A. FLUJO DE CAJA ECONÓMICO (sin financiamiento)
A6: Ingresos por ventas | C6: =Operacion!C$12 -> 3672000 | D6: =Operacion!D$12 -> 4161600 | E6: =Operacion!E$12 -> 4590000 | F6: =Operacion!F$12 -> 4896000 | G6: =Operacion!G$12 -> 5202000 | H6: =Operacion!H$12 -> 5385600 | I6: =Operacion!I$12 -> 5508000 | J6: =Operacion!J$12 -> 5508000 | ... L6: =Operacion!L$12 -> 5508000
A7: Valor residual de activos fijos | C7: 0 | D7: 0 | E7: 0 | F7: 0 | G7: 0 | H7: 0 | I7: 0 | J7: 0 | K7: 0 | L7: =Depreciacion!$B$25 -> 340000
A8: Recuperación del capital de trabajo | C8: 0 | D8: 0 | E8: 0 | F8: 0 | G8: 0 | H8: 0 | I8: 0 | J8: 0 | K8: 0 | L8: =Inversiones!$D$30 -> 695389.55
A9: (-) Costos operativos desembolsables | C9: =-Operacion!C$39 -> -2781558.2 | D9: =-Operacion!D$39 -> -3047827.3 | E9: =-Operacion!E$39 -> -3280812.7 | F9: =-Operacion!F$39 -> -3447230.9 | G9: =-Operacion!G$39 -> -3613649.1 | H9: =-Operacion!H$39 -> -3713500 | I9: =-Operacion!I$39 -> -3780067.3 | J9: =-Operacion!J$39 -> -3780067.3 | ... L9: =-Operacion!L$39 -> -3780067.3
A10: (-) Depreciación y amortización | C10: =-Depreciacion!C$14 -> -112400 | D10: =-Depreciacion!D$14 -> -112400 | E10: =-Depreciacion!E$14 -> -112400 | F10: =-Depreciacion!F$14 -> -112400 | G10: =-Depreciacion!G$14 -> -107900 | H10: =-Depreciacion!H$14 -> -74500 | I10: =-Depreciacion!I$14 -> -74500 | J10: =-Depreciacion!J$14 -> -74500 | ... L10: =-Depreciacion!L$14 -> -74500
A11: Utilidad antes de impuestos (económica) | C11: =C6+C9+C10 -> 778041.82 | D11: =D6+D9+D10 -> 1001372.7 | E11: =E6+E9+E10 -> 1196787.3 | F11: =F6+F9+F10 -> 1336369.1 | G11: =G6+G9+G10 -> 1480450.9 | H11: =H6+H9+H10 -> 1597600 | I11: =I6+I9+I10 -> 1653432.7 | J11: =J6+J9+J10 -> 1653432.7 | ... L11: =L6+L9+L10 -> 1653432.7
A12: (-) Impuesto a la renta | C12: =-MAX(C11,0)*Supuestos!$B$46 -> -229522.34 | D12: =-MAX(D11,0)*Supuestos!$B$46 -> -295404.95 | E12: =-MAX(E11,0)*Supuestos!$B$46 -> -353052.25 | F12: =-MAX(F11,0)*Supuestos!$B$46 -> -394228.88 | G12: =-MAX(G11,0)*Supuestos!$B$46 -> -436733.02 | H12: =-MAX(H11,0)*Supuestos!$B$46 -> -471292 | I12: =-MAX(I11,0)*Supuestos!$B$46 -> -487762.65 | J12: =-MAX(J11,0)*Supuestos!$B$46 -> -487762.65 | ... L12: =-MAX(L11,0)*Supuestos!$B$46 -> -487762.65
A13: Utilidad neta económica | C13: =C11+C12 -> 548519.48 | D13: =D11+D12 -> 705967.77 | E13: =E11+E12 -> 843735.03 | F13: =F11+F12 -> 942140.21 | G13: =G11+G12 -> 1043717.9 | H13: =H11+H12 -> 1126308 | I13: =I11+I12 -> 1165670.1 | J13: =J11+J12 -> 1165670.1 | ... L13: =L11+L12 -> 1165670.1
A14: (+) Depreciación y amortización | C14: =Depreciacion!C$14 -> 112400 | D14: =Depreciacion!D$14 -> 112400 | E14: =Depreciacion!E$14 -> 112400 | F14: =Depreciacion!F$14 -> 112400 | G14: =Depreciacion!G$14 -> 107900 | H14: =Depreciacion!H$14 -> 74500 | I14: =Depreciacion!I$14 -> 74500 | J14: =Depreciacion!J$14 -> 74500 | ... L14: =Depreciacion!L$14 -> 74500
A15: (-) Inversión total | B15: =-Inversiones!$D$33 -> -1965389.5 | C15: 0 | D15: 0 | E15: 0 | F15: 0 | G15: 0 | H15: 0 | I15: 0 | J15: 0 | K15: 0 | L15: 0
A16: FLUJO DE CAJA ECONÓMICO | B16: =B15 -> -1965389.5 | C16: =C13+C14+C7+C8 -> 660919.48 | D16: =D13+D14+D7+D8 -> 818367.77 | E16: =E13+E14+E7+E8 -> 956135.03 | F16: =F13+F14+F7+F8 -> 1054540.2 | G16: =G13+G14+G7+G8 -> 1151617.9 | H16: =H13+H14+H7+H8 -> 1200808 | I16: =I13+I14+I7+I8 -> 1240170.1 | J16: =J13+J14+J7+J8 -> 1240170.1 | ... L16: =L13+L14+L7+L8 -> 2275559.6
A18: B. FLUJO DE CAJA FINANCIERO (con financiamiento)
A19: Flujo de caja económico | B19: =B16 -> -1965389.5 | C19: =C16 -> 660919.48 | D19: =D16 -> 818367.77 | E19: =E16 -> 956135.03 | F19: =F16 -> 1054540.2 | G19: =G16 -> 1151617.9 | H19: =H16 -> 1200808 | I19: =I16 -> 1240170.1 | ... L19: =L16 -> 2275559.6
A20: (+) Préstamo recibido | B20: =Inversiones!$D$37 -> 1179233.7 | C20: 0 | D20: 0 | E20: 0 | F20: 0 | G20: 0 | H20: 0 | I20: 0 | J20: 0 | K20: 0 | L20: 0
A21: (-) Amortización del principal | C21: =-Financiamiento!$D$10 -> -178398.66 | D21: =-Financiamiento!$D$11 -> -203374.47 | E21: =-Financiamiento!$D$12 -> -231846.9 | F21: =-Financiamiento!$D$13 -> -264305.46 | G21: =-Financiamiento!$D$14 -> -301308.23 | H21: =-Financiamiento!$D$15 -> 0 | I21: =-Financiamiento!$D$16 -> 0 | J21: =-Financiamiento!$D$17 -> 0 | K21: =-Financiamiento!$D$18 -> 0 | L21: =-Financiamiento!$D$19 -> 0
A22: (-) Intereses | C22: =-Financiamiento!$C$10 -> -165092.72 | D22: =-Financiamiento!$C$11 -> -140116.91 | E22: =-Financiamiento!$C$12 -> -111644.48 | F22: =-Financiamiento!$C$13 -> -79185.917 | G22: =-Financiamiento!$C$14 -> -42183.152 | H22: =-Financiamiento!$C$15 -> 0 | I22: =-Financiamiento!$C$16 -> 0 | J22: =-Financiamiento!$C$17 -> 0 | K22: =-Financiamiento!$C$18 -> 0 | L22: =-Financiamiento!$C$19 -> 0
A23: (+) Escudo fiscal de los intereses | C23: =Financiamiento!$C$10*Supuestos!$B$46 -> 48702.353 | D23: =Financiamiento!$C$11*Supuestos!$B$46 -> 41334.488 | E23: =Financiamiento!$C$12*Supuestos!$B$46 -> 32935.123 | F23: =Financiamiento!$C$13*Supuestos!$B$46 -> 23359.846 | G23: =Financiamiento!$C$14*Supuestos!$B$46 -> 12444.03 | H23: =Financiamiento!$C$15*Supuestos!$B$46 -> 0 | I23: =Financiamiento!$C$16*Supuestos!$B$46 -> 0 | J23: =Financiamiento!$C$17*Supuestos!$B$46 -> 0 | K23: =Financiamiento!$C$18*Supuestos!$B$46 -> 0 | L23: =Financiamiento!$C$19*Supuestos!$B$46 -> 0
A24: FLUJO DE CAJA FINANCIERO | B24: =B19+B20 -> -786155.82 | C24: =C19+C20+C21+C22+C23 -> 366130.45 | D24: =D19+D20+D21+D22+D23 -> 516210.88 | E24: =E19+E20+E21+E22+E23 -> 645578.77 | F24: =F19+F20+F21+F22+F23 -> 734408.67 | G24: =G19+G20+G21+G22+G23 -> 820570.54 | H24: =H19+H20+H21+H22+H23 -> 1200808 | I24: =I19+I20+I21+I22+I23 -> 1240170.1 | J24: =J19+J20+J21+J22+J23 -> 1240170.1 | ... L24: =L19+L20+L21+L22+L23 -> 2275559.6

Sheet Evaluacion
A1: EVALUACIÓN ECONÓMICA Y FINANCIERA
A2: Estos son los resultados que van al Capítulo VIII del informe.
A4: A. TASAS DE DESCUENTO
A5: COK (costo de oportunidad del capital) | B5: =Supuestos!$B$47 -> 0.15
A6: Costo de la deuda después de impuestos | B6: =Supuestos!$B$51*(1-Supuestos!$B$46) -> 0.0987
A7: WACC (costo promedio ponderado de capital) | B7: =Supuestos!$B$50*B6+(1-Supuestos!$B$50)*B5 -> 0.11922 | C7: WACC = %deuda × Kd × (1−t) + %propio × COK
A9: TASAS USADAS PARA DESCONTAR (puedes cambiarlas)
A10: Tasa de descuento del flujo ECONÓMICO | B10: =B7 -> 0.11922 | C10: Por defecto: WACC | D10: Si tu docente pide descontar el flujo económico al COK, escribe aquí =B5
A11: Tasa de descuento del flujo FINANCIERO | B11: =B5 -> 0.15 | C11: Por defecto: COK | D11: Es la tasa que exige el accionista sobre su aporte propio
A12: Convención usada: el flujo económico se descuenta al WACC (evalúa el negocio completo) y el financiero al COK (evalúa lo que gana el accionista). Declara esta convención en tu informe.
A14: B. INDICADORES DE RENTABILIDAD
A15: Indicador | B15: Evaluación económica | C15: Evaluación financiera | D15: Criterio de decisión
A16: VAN — Valor Actual Neto (S/) | B16: =NPV($B$10,FlujoCaja!$C$16:$L$16)+FlujoCaja!$B$16 -> 4154359.2 | C16: =NPV($B$11,FlujoCaja!$C$24:$L$24)+FlujoCaja!$B$24 -> 3480695.1 | D16: Se acepta si VAN > 0
A17: TIR — Tasa Interna de Retorno | B17: =IFERROR(IRR(FlujoCaja!$B$16:$L$16),"n.d.") -> 0.44902559 | C17: =IFERROR(IRR(FlujoCaja!$B$24:$L$24),"n.d.") -> 0.70308622 | D17: Se acepta si TIR > tasa de descuento
A18: B/C — Relación beneficio/costo | B18: =IFERROR(B42/B43,0) -> 1.1774927 | D18: Se acepta si B/C > 1
A19: PRI — Periodo de recuperación (años) | B19: =IFERROR(COUNTIF(B38:L38,"<0")-1+ABS(INDEX(B38:L38,COUNTIF(B38:L38,"<0")))/INDEX(FlujoCaja!$C$16:$L$16,COUNTIF(B38:L38,"<0")),"n.d.") -> 2.5084034 | D19: Se acepta si el PRI es menor que el horizonte del proyecto
A20: Utilidad neta promedio anual (S/) | B20: =AVERAGE(EERR!C15:L15) -> 949362.13
A22: C. PUNTO DE EQUILIBRIO
A23: Concepto | B23: Unidad | C23: Año 1 | D23: Año 2 | E23: Año 3 | F23: Año 4 | G23: Año 5 | H23: Año 6 | I23: Año 7 | J23: Año 8 | K23: Año 9 | L23: Año 10
A24: Punto de equilibrio (kg/año) | C24: =IF((Operacion!C$9-Operacion!C$40)<=0,0,Operacion!C$33/(Operacion!C$9-Operacion!C$40)) -> 202343.26 | D24: =IF((Operacion!D$9-Operacion!D$40)<=0,0,Operacion!D$33/(Operacion!D$9-Operacion!D$40)) -> 202343.26 | E24: =IF((Operacion!E$9-Operacion!E$40)<=0,0,Operacion!E$33/(Operacion!E$9-Operacion!E$40)) -> 202343.26 | F24: =IF((Operacion!F$9-Operacion!F$40)<=0,0,Operacion!F$33/(Operacion!F$9-Operacion!F$40)) -> 202343.26 | G24: =IF((Operacion!G$9-Operacion!G$40)<=0,0,Operacion!G$33/(Operacion!G$9-Operacion!G$40)) -> 202343.26 | H24: =IF((Operacion!H$9-Operacion!H$40)<=0,0,Operacion!H$33/(Operacion!H$9-Operacion!H$40)) -> 202343.26 | I24: =IF((Operacion!I$9-Operacion!I$40)<=0,0,Operacion!I$33/(Operacion!I$9-Operacion!I$40)) -> 202343.26 | J24: =IF((Operacion!J$9-Operacion!J$40)<=0,0,Operacion!J$33/(Operacion!J$9-Operacion!J$40)) -> 202343.26 | ... L24: =IF((Operacion!L$9-Operacion!L$40)<=0,0,Operacion!L$33/(Operacion!L$9-Operacion!L$40)) -> 202343.26
A25: Punto de equilibrio (S/ al año) | C25: =C24*Operacion!C$9 -> 1719917.7 | D25: =D24*Operacion!D$9 -> 1719917.7 | E25: =E24*Operacion!E$9 -> 1719917.7 | F25: =F24*Operacion!F$9 -> 1719917.7 | G25: =G24*Operacion!G$9 -> 1719917.7 | H25: =H24*Operacion!H$9 -> 1719917.7 | I25: =I24*Operacion!I$9 -> 1719917.7 | J25: =J24*Operacion!J$9 -> 1719917.7 | ... L25: =L24*Operacion!L$9 -> 1719917.7
A26: Punto de equilibrio como % de la producción | C26: =IF(Operacion!C$7=0,0,C24/Operacion!C$7) -> 0.46838717 | D26: =IF(Operacion!D$7=0,0,D24/Operacion!D$7) -> 0.4132828 | E26: =IF(Operacion!E$7=0,0,E24/Operacion!E$7) -> 0.37470974 | F26: =IF(Operacion!F$7=0,0,F24/Operacion!F$7) -> 0.35129038 | G26: =IF(Operacion!G$7=0,0,G24/Operacion!G$7) -> 0.33062624 | H26: =IF(Operacion!H$7=0,0,H24/Operacion!H$7) -> 0.31935489 | I26: =IF(Operacion!I$7=0,0,I24/Operacion!I$7) -> 0.31225812 | J26: =IF(Operacion!J$7=0,0,J24/Operacion!J$7) -> 0.31225812 | ... L26: =IF(Operacion!L$7=0,0,L24/Operacion!L$7) -> 0.31225812
A28: Lectura: si el punto de equilibrio está muy por debajo del 100 %, el proyecto tiene holgura frente a caídas de venta.
A30: D. AUXILIAR — COEFICIENTES PARA EL ANÁLISIS DE SENSIBILIDAD
A31: No modificar. Se usan en la hoja Sensibilidad.
A32: Concepto | B32: Unidad | C32: Año 1 | D32: Año 2 | E32: Año 3 | F32: Año 4 | G32: Año 5 | H32: Año 6 | I32: Año 7 | J32: Año 8 | K32: Año 9 | L32: Año 10
A33: Ingresos después de impuestos | C33: =Operacion!C$12*(1-Supuestos!$B$46) -> 2588760 | D33: =Operacion!D$12*(1-Supuestos!$B$46) -> 2933928 | E33: =Operacion!E$12*(1-Supuestos!$B$46) -> 3235950 | F33: =Operacion!F$12*(1-Supuestos!$B$46) -> 3451680 | G33: =Operacion!G$12*(1-Supuestos!$B$46) -> 3667410 | H33: =Operacion!H$12*(1-Supuestos!$B$46) -> 3796848 | I33: =Operacion!I$12*(1-Supuestos!$B$46) -> 3883140 | J33: =Operacion!J$12*(1-Supuestos!$B$46) -> 3883140 | ... L33: =Operacion!L$12*(1-Supuestos!$B$46) -> 3883140
A34: Costo de materia prima después de impuestos | C34: =Operacion!C$15*(1-Supuestos!$B$46) -> 996741.82 | D34: =Operacion!D$15*(1-Supuestos!$B$46) -> 1129640.7 | E34: =Operacion!E$15*(1-Supuestos!$B$46) -> 1245927.3 | F34: =Operacion!F$15*(1-Supuestos!$B$46) -> 1328989.1 | G34: =Operacion!G$15*(1-Supuestos!$B$46) -> 1412050.9 | H34: =Operacion!H$15*(1-Supuestos!$B$46) -> 1461888 | I34: =Operacion!I$15*(1-Supuestos!$B$46) -> 1495112.7 | J34: =Operacion!J$15*(1-Supuestos!$B$46) -> 1495112.7 | ... L34: =Operacion!L$15*(1-Supuestos!$B$46) -> 1495112.7
A35: Margen de contribución después de impuestos | C35: =(Operacion!C$12-Operacion!C$20)*(1-Supuestos!$B$46) -> 1180862.2 | D35: =(Operacion!D$12-Operacion!D$20)*(1-Supuestos!$B$46) -> 1338310.5 | E35: =(Operacion!E$12-Operacion!E$20)*(1-Supuestos!$B$46) -> 1476077.7 | F35: =(Operacion!F$12-Operacion!F$20)*(1-Supuestos!$B$46) -> 1574482.9 | G35: =(Operacion!G$12-Operacion!G$20)*(1-Supuestos!$B$46) -> 1672888.1 | H35: =(Operacion!H$12-Operacion!H$20)*(1-Supuestos!$B$46) -> 1731931.2 | I35: =(Operacion!I$12-Operacion!I$20)*(1-Supuestos!$B$46) -> 1771293.3 | J35: =(Operacion!J$12-Operacion!J$20)*(1-Supuestos!$B$46) -> 1771293.3 | ... L35: =(Operacion!L$12-Operacion!L$20)*(1-Supuestos!$B$46) -> 1771293.3
A36: Beneficios totales (ingresos + residual + capital de trabajo) | C36: =Operacion!C$12+FlujoCaja!C$7+FlujoCaja!C$8 -> 3672000 | D36: =Operacion!D$12+FlujoCaja!D$7+FlujoCaja!D$8 -> 4161600 | E36: =Operacion!E$12+FlujoCaja!E$7+FlujoCaja!E$8 -> 4590000 | F36: =Operacion!F$12+FlujoCaja!F$7+FlujoCaja!F$8 -> 4896000 | G36: =Operacion!G$12+FlujoCaja!G$7+FlujoCaja!G$8 -> 5202000 | H36: =Operacion!H$12+FlujoCaja!H$7+FlujoCaja!H$8 -> 5385600 | I36: =Operacion!I$12+FlujoCaja!I$7+FlujoCaja!I$8 -> 5508000 | J36: =Operacion!J$12+FlujoCaja!J$7+FlujoCaja!J$8 -> 5508000 | ... L36: =Operacion!L$12+FlujoCaja!L$7+FlujoCaja!L$8 -> 6543389.5
A37: Egresos totales (costos operativos + impuestos) | C37: =Operacion!C$39-FlujoCaja!C$12 -> 3011080.5 | D37: =Operacion!D$39-FlujoCaja!D$12 -> 3343232.2 | E37: =Operacion!E$39-FlujoCaja!E$12 -> 3633865 | F37: =Operacion!F$39-FlujoCaja!F$12 -> 3841459.8 | G37: =Operacion!G$39-FlujoCaja!G$12 -> 4050382.1 | H37: =Operacion!H$39-FlujoCaja!H$12 -> 4184792 | I37: =Operacion!I$39-FlujoCaja!I$12 -> 4267829.9 | J37: =Operacion!J$39-FlujoCaja!J$12 -> 4267829.9 | ... L37: =Operacion!L$39-FlujoCaja!L$12 -> 4267829.9
A38: Flujo económico acumulado | B38: =FlujoCaja!$B$16 -> -1965389.5 | C38: =B38+FlujoCaja!C$16 -> -1304470.1 | D38: =C38+FlujoCaja!D$16 -> -486102.29 | E38: =D38+FlujoCaja!E$16 -> 470032.74 | F38: =E38+FlujoCaja!F$16 -> 1524572.9 | G38: =F38+FlujoCaja!G$16 -> 2676190.8 | H38: =G38+FlujoCaja!H$16 -> 3876998.8 | I38: =H38+FlujoCaja!I$16 -> 5117168.9 | J38: =I38+FlujoCaja!J$16 -> 6357339 | ... L38: =K38+FlujoCaja!L$16 -> 9873068.7
A39: VP de ingresos netos de impuesto (coef. precio) | B39: =NPV($B$10,C33:L33) -> 19193250
A40: VP del costo de materia prima neto (coef. MP) | B40: =NPV($B$10,C34:L34) -> 7389914.3
A41: VP del margen de contribución neto (coef. volumen) | B41: =NPV($B$10,C35:L35) -> 8754995.7
A42: VP de beneficios totales | B42: =NPV($B$10,C36:L36) -> 27560166
A43: VP de egresos totales + inversión | B43: =NPV($B$10,C37:L37)+Inversiones!$D$33 -> 23405807

Sheet Sensibilidad
A1: ANÁLISIS DE SENSIBILIDAD Y ESCENARIOS
A2: Muestra qué variable pone en riesgo el proyecto. Es la sección que más se pregunta en la sustentación.
A4: VAN económico del escenario base (S/) | B4: =Evaluacion!$B$16 -> 4154359.2
A6: A. SENSIBILIDAD A UNA VARIABLE
A7: Variación | B7: VAN si cambia el PRECIO | C7: VAN si cambia el COSTO DE MP | D7: VAN si cambia el VOLUMEN
A8: -0.2 | B8: =$B$4+$A8*Evaluacion!$B$39 -> 315709.24 | C8: =$B$4-$A8*Evaluacion!$B$40 -> 5632342 | D8: =$B$4+$A8*Evaluacion!$B$41 -> 2403360
A9: -0.15 | B9: =$B$4+$A9*Evaluacion!$B$39 -> 1275371.7 | C9: =$B$4-$A9*Evaluacion!$B$40 -> 5262846.3 | D9: =$B$4+$A9*Evaluacion!$B$41 -> 2841109.8
A10: -0.1 | B10: =$B$4+$A10*Evaluacion!$B$39 -> 2235034.2 | C10: =$B$4-$A10*Evaluacion!$B$40 -> 4893350.6 | D10: =$B$4+$A10*Evaluacion!$B$41 -> 3278859.6
A11: -0.05 | B11: =$B$4+$A11*Evaluacion!$B$39 -> 3194696.7 | C11: =$B$4-$A11*Evaluacion!$B$40 -> 4523854.9 | D11: =$B$4+$A11*Evaluacion!$B$41 -> 3716609.4
A12: 0 | B12: =$B$4+$A12*Evaluacion!$B$39 -> 4154359.2 | C12: =$B$4-$A12*Evaluacion!$B$40 -> 4154359.2 | D12: =$B$4+$A12*Evaluacion!$B$41 -> 4154359.2
A13: 0.05 | B13: =$B$4+$A13*Evaluacion!$B$39 -> 5114021.6 | C13: =$B$4-$A13*Evaluacion!$B$40 -> 3784863.4 | D13: =$B$4+$A13*Evaluacion!$B$41 -> 4592108.9
A14: 0.1 | B14: =$B$4+$A14*Evaluacion!$B$39 -> 6073684.1 | C14: =$B$4-$A14*Evaluacion!$B$40 -> 3415367.7 | D14: =$B$4+$A14*Evaluacion!$B$41 -> 5029858.7
A15: 0.15 | B15: =$B$4+$A15*Evaluacion!$B$39 -> 7033346.6 | C15: =$B$4-$A15*Evaluacion!$B$40 -> 3045872 | D15: =$B$4+$A15*Evaluacion!$B$41 -> 5467608.5
A16: 0.2 | B16: =$B$4+$A16*Evaluacion!$B$39 -> 7993009.1 | C16: =$B$4-$A16*Evaluacion!$B$40 -> 2676376.3 | D16: =$B$4+$A16*Evaluacion!$B$41 -> 5905358.3
A18: VARIACIÓN CRÍTICA (la que lleva el VAN a cero)
A19: Caída máxima tolerable del precio | B19: =-$B$4/Evaluacion!$B$39 -> -0.21644897
A20: Alza máxima tolerable del costo de materia prima | B20: =$B$4/Evaluacion!$B$40 -> 0.56216608
A21: Caída máxima tolerable del volumen de ventas | B21: =-$B$4/Evaluacion!$B$41 -> -0.47451299
A22: La variable con el porcentaje más pequeño es la variable crítica del proyecto.
A24: B. ANÁLISIS DE ESCENARIOS
A25: Escenario | B25: Δ Precio | C25: Δ Costo MP | D25: Δ Volumen | E25: VAN económico (S/) | F25: Decisión
A26: Pesimista | B26: -0.1 | C26: 0.15 | D26: -0.15 | E26: =$B$4+B26*Evaluacion!$B$39-C26*Evaluacion!$B$40+D26*Evaluacion!$B$41 -> -186702.29 | F26: =IF(E26>0,"Viable","No viable") -> No viable
A27: Moderado (base) | B27: 0 | C27: 0 | D27: 0 | E27: =$B$4+B27*Evaluacion!$B$39-C27*Evaluacion!$B$40+D27*Evaluacion!$B$41 -> 4154359.2 | F27: =IF(E27>0,"Viable","No viable") -> Viable
A28: Optimista | B28: 0.08 | C28: -0.05 | D28: 0.1 | E28: =$B$4+B28*Evaluacion!$B$39-C28*Evaluacion!$B$40+D28*Evaluacion!$B$41 -> 6934814.4 | F28: =IF(E28>0,"Viable","No viable") -> Viable
A30: CÓMO SE CALCULA
A31: El modelo es lineal en precio, costo de materia prima y volumen, así que el efecto sobre el VAN se obtiene
A32: multiplicando la variación por el valor presente del rubro afectado, neto de impuesto a la renta:
A33: • Precio: ΔVAN = Δ% × VP(ingresos × (1 − t))
A34: • Costo MP: ΔVAN = −Δ% × VP(costo de materia prima × (1 − t))
A35: • Volumen: ΔVAN = Δ% × VP((ingresos − costos variables) × (1 − t))
A36: Los tres valores presentes están calculados en la hoja Evaluacion, sección D.
A37: Supuesto: la utilidad antes de impuestos se mantiene positiva en el escenario evaluado. Si un escenario muy
A38: pesimista da pérdidas, verifica el resultado cambiando el dato directamente en la hoja Supuestos.
